Workbook

Sheet Orders
A1: order_id | B1: supplier_id | C1: product_id | D1: quantity | E1: order_date | F1: Order_date_
A2: 3999 | B2: 49 | C2: 36 | D2: 17 | E2: 45217 | F2: 45217
A3: 3995 | B3: 28 | C3: 199 | D3: 35 | E3: 45142 | F3: 45142
A4: 3994 | B4: 49 | C4: 130 | D4: 14 | E4: 45046 | F4: 45046
A5: 3992 | B5: 39 | C5: 87 | D5: 62 | E5: 45118 | F5: 45118
A6: 5 | B6: 1 | C6: 108 | D6: 63 | E6: 45101 | F6: 45101
A7: 6 | B7: 28 | C7: 93 | D7: 82 | E7: 44981 | F7: 44981
A8: 3988 | B8: 12 | C8: 193 | D8: 3 | E8: 45206 | F8: 45206
A9: 8 | B9: 47 | C9: 134 | D9: 84 | E9: 45017 | F9: 45017
A10: 3982 | B10: 37 | C10: 97 | D10: 85 | E10: 45117 | F10: 45117
A11: 3975 | B11: 44 | C11: 74 | D11: 27 | E11: 45257 | F11: 45257
A12: 3968 | B12: 19 | C12: 67 | D12: 90 | E12: 45017 | F12: 45017
A13: 3967 | B13: 13 | C13: 70 | D13: 26 | E13: 45042 | F13: 45042
... A1227: 1226 | B1227: 44 | C1227: 109 | D1227: 14 | E1227: 45036 | F1227: 45036

Sheet Clean_Processing
A1: order_id | B1: supplier_id | C1: product_id | D1: quantity | E1: Order_date2 | F1: Year | G1: Product_name | H1: Supplier_name | I1: Product Category | J1: Vehicle Id | K1: Vehicle type | L1: Delivery_date | M1: Delivery_status | N1: Delivery_cost $ | O1: Delivery_profit $ | P1: Delivery _profit_margin% | Q1: Unit_cost $ | R1: Total_revenue $ | S1: Profit $ | T1: Profit_margin% | U1: Delivery_days | V1: Delivery_rate | W1: Destination_city
A2: 1 | B2: 50 | C2: 78 | D2: 88 | E2: 45283 | F2: 2023 | G2: =INDEX(Products!B:B, MATCH(C2,Clean_Processing!A:A, 0)) -> Enter | H2: =INDEX(Suppliers!B:B, MATCH(B2, Clean_Processing!A:A, 0)) -> Waters-Robinson | I2: =INDEX(Products!C:C, MATCH(B2,Clean_Processing!A:A, 0)) -> Medical | J2: =INDEX(Shipments!C:C, MATCH(B2,Clean_Processing!A:A, 0)) -> 9 | K2: =INDEX(Shipments!D:D, MATCH(C2,Clean_Processing!A:A, 0)) -> Drone | L2: 45044 | M2: Delivered | N2: =IFERROR(INDEX(Shipments!G:G, MATCH(J2, Clean_Processing!C:C, 0)), "") -> 398.406 | O2: 10767.034 | P2: 0.96431793 | Q2: =INDEX(Products!D:D, MATCH(C2, Clean_Processing!A:A, 0)) -> 126.88 | R2: 11165.44 | S2: 10640.154 | T2: 0.95295429 | W2: Crystalland
A3: 2 | B3: 8 | C3: 145 | D3: 6 | E3: 45234 | F3: 2023 | G3: =INDEX(Products!B:B, MATCH(C3,Clean_Processing!A:A, 0)) -> Economic | H3: =INDEX(Suppliers!B:B, MATCH(B3, Clean_Processing!A:A, 0)) -> Andrews-Jordan | I3: =INDEX(Products!C:C, MATCH(B3,Clean_Processing!A:A, 0)) -> Medical | J3: =INDEX(Shipments!C:C, MATCH(B3,Clean_Processing!A:A, 0)) -> 27 | K3: =INDEX(Shipments!D:D, MATCH(C3,Clean_Processing!A:A, 0)) -> Van | L3: 45156 | M3: Delivered | N3: =IFERROR(INDEX(Shipments!G:G, MATCH(J3, Clean_Processing!C:C, 0)), "") -> 49.753309 | O3: 420.10669 | P3: 0.89411035 | Q3: =INDEX(Products!D:D, MATCH(C3, Clean_Processing!A:A, 0)) -> 78.31 | R3: 469.86 | S3: 341.79669 | T3: 0.72744369 | W3: North Stephanie
A4: 3 | B4: 35 | C4: 110 | D4: 85 | E4: 45104 | F4: 2023 | G4: =INDEX(Products!B:B, MATCH(C4,Clean_Processing!A:A, 0)) -> Thousand | H4: =INDEX(Suppliers!B:B, MATCH(B4, Clean_Processing!A:A, 0)) -> Braun-Miller | I4: =INDEX(Products!C:C, MATCH(B4,Clean_Processing!A:A, 0)) -> Food | J4: =INDEX(Shipments!C:C, MATCH(B4,Clean_Processing!A:A, 0)) -> 68 | K4: =INDEX(Shipments!D:D, MATCH(C4,Clean_Processing!A:A, 0)) -> 0 | L4: 45120 | M4: Delivered | N4: =IFERROR(INDEX(Shipments!G:G, MATCH(J4, Clean_Processing!C:C, 0)), "") -> 74.899801 | O4: 679.0502 | P4: 0.90065681 | Q4: =INDEX(Products!D:D, MATCH(C4, Clean_Processing!A:A, 0)) -> 8.87 | R4: 753.95 | S4: 670.1802 | T4: 0.8888921 | U4: 16 | V4: Slow | W4: Kellyside
A5: 4 | B5: 5 | C5: 130 | D5: 83 | E5: 45116 | F5: 2023 | G5: =INDEX(Products!B:B, MATCH(C5,Clean_Processing!A:A, 0)) -> Three | H5: =INDEX(Suppliers!B:B, MATCH(B5, Clean_Processing!A:A, 0)) -> Logan-Fernandez | I5: =INDEX(Products!C:C, MATCH(B5,Clean_Processing!A:A, 0)) -> Clothing | J5: =INDEX(Shipments!C:C, MATCH(B5,Clean_Processing!A:A, 0)) -> 44 | K5: =INDEX(Shipments!D:D, MATCH(C5,Clean_Processing!A:A, 0)) -> 0 | L5: 45273 | M5: Delivered | N5: =IFERROR(INDEX(Shipments!G:G, MATCH(J5, Clean_Processing!C:C, 0)), "") -> 454.92062 | O5: 11327.759 | P5: 0.96139073 | Q5: =INDEX(Products!D:D, MATCH(C5, Clean_Processing!A:A, 0)) -> 141.96 | R5: 11782.68 | S5: 11185.799 | T5: 0.94934254 | U5: 157 | V5: Slow | W5: West Kirk
A6: 5 | B6: 1 | C6: 108 | D6: 63 | E6: 45101 | F6: 2023 | G6: =INDEX(Products!B:B, MATCH(C6,Clean_Processing!A:A, 0)) -> Interesting | H6: =INDEX(Suppliers!B:B, MATCH(B6, Clean_Processing!A:A, 0)) -> Robinson, Beasley and Hall | I6: =INDEX(Products!C:C, MATCH(B6,Clean_Processing!A:A, 0)) -> Electronics | J6: =INDEX(Shipments!C:C, MATCH(B6,Clean_Processing!A:A, 0)) -> 28 | K6: =INDEX(Shipments!D:D, MATCH(C6,Clean_Processing!A:A, 0)) -> 0 | L6: 45090 | M6: Delivered | N6: =IFERROR(INDEX(Shipments!G:G, MATCH(J6, Clean_Processing!C:C, 0)), "") -> 362.48678 | O6: 30739.353 | P6: 0.98834517 | Q6: =INDEX(Products!D:D, MATCH(C6, Clean_Processing!A:A, 0)) -> 493.68 | R6: 31101.84 | S6: 30245.673 | T6: 0.97247215 | W6: West Lindsey
A7: 6 | B7: 28 | C7: 93 | D7: 82 | E7: 44981 | F7: 2023 | G7: =INDEX(Products!B:B, MATCH(C7,Clean_Processing!A:A, 0)) -> Local | H7: =INDEX(Suppliers!B:B, MATCH(B7, Clean_Processing!A:A, 0)) -> Brown, Maynard and Campbell | I7: =INDEX(Products!C:C, MATCH(B7,Clean_Processing!A:A, 0)) -> Electronics | J7: =INDEX(Shipments!C:C, MATCH(B7,Clean_Processing!A:A, 0)) -> 66 | K7: =INDEX(Shipments!D:D, MATCH(C7,Clean_Processing!A:A, 0)) -> Bike | L7: 45237 | M7: Delivered | N7: =IFERROR(INDEX(Shipments!G:G, MATCH(J7, Clean_Processing!C:C, 0)), "") -> 194.08343 | O7: 3160.5366 | P7: 0.94214444 | Q7: =INDEX(Products!D:D, MATCH(C7, Clean_Processing!A:A, 0)) -> 40.91 | R7: 3354.62 | S7: 3119.6266 | T7: 0.92994931 | U7: 256 | V7: Slow | W7: Port Marybury
A8: 7 | B8: 46 | C8: 40 | D8: 56 | E8: 45162 | F8: 2023 | G8: =INDEX(Products!B:B, MATCH(C8,Clean_Processing!A:A, 0)) -> Individual | H8: =INDEX(Suppliers!B:B, MATCH(B8, Clean_Processing!A:A, 0)) -> Bailey PLC | I8: =INDEX(Products!C:C, MATCH(B8,Clean_Processing!A:A, 0)) -> Medical | J8: =INDEX(Shipments!C:C, MATCH(B8,Clean_Processing!A:A, 0)) -> 19 | K8: =INDEX(Shipments!D:D, MATCH(C8,Clean_Processing!A:A, 0)) -> Drone | L8: 45286 | M8: Delivered | N8: =IFERROR(INDEX(Shipments!G:G, MATCH(J8, Clean_Processing!C:C, 0)), "") -> 194.0078 | O8: 23260.472 | P8: 0.99172833 | Q8: =INDEX(Products!D:D, MATCH(C8, Clean_Processing!A:A, 0)) -> 418.83 | R8: 23454.48 | S8: 22841.642 | T8: 0.97387118 | U8: 124 | V8: Slow | W8: North Amber
A9: 8 | B9: 47 | C9: 134 | D9: 84 | E9: 45017 | F9: 2023 | G9: =INDEX(Products!B:B, MATCH(C9,Clean_Processing!A:A, 0)) -> Traditional | H9: =INDEX(Suppliers!B:B, MATCH(B9, Clean_Processing!A:A, 0)) -> Gutierrez and Sons | I9: =INDEX(Products!C:C, MATCH(B9,Clean_Processing!A:A, 0)) -> Electronics | J9: =INDEX(Shipments!C:C, MATCH(B9,Clean_Processing!A:A, 0)) -> 45 | K9: =INDEX(Shipments!D:D, MATCH(C9,Clean_Processing!A:A, 0)) -> Bike | L9: 45039 | M9: Delivered | N9: =IFERROR(INDEX(Shipments!G:G, MATCH(J9, Clean_Processing!C:C, 0)), "") -> 207.67191 | O9: 11104.608 | P9: 0.98164191 | Q9: =INDEX(Products!D:D, MATCH(C9, Clean_Processing!A:A, 0)) -> 134.67 | R9: 11312.28 | S9: 10969.938 | T9: 0.96973714 | U9: 22 | V9: Slow | W9: West James
A10: 9 | B10: 40 | C10: 138 | D10: 100 | E10: 45065 | F10: 2023 | G10: =INDEX(Products!B:B, MATCH(C10,Clean_Processing!A:A, 0)) -> Choose | H10: =INDEX(Suppliers!B:B, MATCH(B10, Clean_Processing!A:A, 0)) -> Ross Inc | I10: =INDEX(Products!C:C, MATCH(B10,Clean_Processing!A:A, 0)) -> Food | J10: =INDEX(Shipments!C:C, MATCH(B10,Clean_Processing!A:A, 0)) -> 48 | K10: =INDEX(Shipments!D:D, MATCH(C10,Clean_Processing!A:A, 0)) -> 0 | L10: 45075 | M10: Delivered | N10: =IFERROR(INDEX(Shipments!G:G, MATCH(J10, Clean_Processing!C:C, 0)), "") -> 438.83986 | O10: 540.16014 | P10: 0.55174682 | Q10: =INDEX(Products!D:D, MATCH(C10, Clean_Processing!A:A, 0)) -> 9.79 | R10: 979 | S10: 530.37014 | T10: 0.54174682 | U10: 10 | V10: Normal | W10: New Harold
A11: 10 | B11: 30 | C11: 112 | D11: 94 | E11: 45174 | F11: 2023 | G11: =INDEX(Products!B:B, MATCH(C11,Clean_Processing!A:A, 0)) -> Among | H11: =INDEX(Suppliers!B:B, MATCH(B11, Clean_Processing!A:A, 0)) -> Burton-Logan | I11: =INDEX(Products!C:C, MATCH(B11,Clean_Processing!A:A, 0)) -> Furniture | J11: =INDEX(Shipments!C:C, MATCH(B11,Clean_Processing!A:A, 0)) -> 17 | K11: =INDEX(Shipments!D:D, MATCH(C11,Clean_Processing!A:A, 0)) -> 0 | L11: 45281 | M11: Delivered | N11: =IFERROR(INDEX(Shipments!G:G, MATCH(J11, Clean_Processing!C:C, 0)), "") -> 480.10591 | O11: 13919.754 | P11: 0.96665899 | Q11: =INDEX(Products!D:D, MATCH(C11, Clean_Processing!A:A, 0)) -> 153.19 | R11: 14399.86 | S11: 13766.564 | T11: 0.95602069 | U11: 107 | V11: Slow | W11: West Tara
A12: 11 | B12: 18 | C12: 83 | D12: 32 | E12: 45230 | F12: 2023 | G12: =INDEX(Products!B:B, MATCH(C12,Clean_Processing!A:A, 0)) -> Resource | H12: =INDEX(Suppliers!B:B, MATCH(B12, Clean_Processing!A:A, 0)) -> Walsh and Sons | I12: =INDEX(Products!C:C, MATCH(B12,Clean_Processing!A:A, 0)) -> Medical | J12: =INDEX(Shipments!C:C, MATCH(B12,Clean_Processing!A:A, 0)) -> 7 | K12: =INDEX(Shipments!D:D, MATCH(C12,Clean_Processing!A:A, 0)) -> Bike | L12: 45291 | M12: Delivered | N12: =IFERROR(INDEX(Shipments!G:G, MATCH(J12, Clean_Processing!C:C, 0)), "") -> 277.62922 | O12: 8163.3308 | P12: 0.96710928 | Q12: =INDEX(Products!D:D, MATCH(C12, Clean_Processing!A:A, 0)) -> 263.78 | R12: 8440.96 | S12: 7899.5508 | T12: 0.93585928 | U12: 61 | V12: Slow | W12: Austinstad
A13: 12 | B13: 18 | C13: 116 | D13: 32 | E13: 44971 | F13: 2023 | G13: =INDEX(Products!B:B, MATCH(C13,Clean_Processing!A:A, 0)) -> Suffer | H13: =INDEX(Suppliers!B:B, MATCH(B13, Clean_Processing!A:A, 0)) -> Walsh and Sons | I13: =INDEX(Products!C:C, MATCH(B13,Clean_Processing!A:A, 0)) -> Medical | J13: =INDEX(Shipments!C:C, MATCH(B13,Clean_Processing!A:A, 0)) -> 7 | K13: =INDEX(Shipments!D:D, MATCH(C13,Clean_Processing!A:A, 0)) -> Bike | L13: 45121 | M13: Delivered | N13: =IFERROR(INDEX(Shipments!G:G, MATCH(J13, Clean_Processing!C:C, 0)), "") -> 277.62922 | O13: 1710.8508 | P13: 0.86038118 | Q13: =INDEX(Products!D:D, MATCH(C13, Clean_Processing!A:A, 0)) -> 62.14 | R13: 1988.48 | S13: 1648.7108 | T13: 0.82913118 | U13: 150 | V13: Slow | W13: Timothyland
A14: 13 | B14: 37 | C14: 157 | D14: 86 | E14: 45164 | F14: 2023 | G14: =INDEX(Products!B:B, MATCH(C14,Clean_Processing!A:A, 0)) -> On | H14: =INDEX(Suppliers!B:B, MATCH(B14, Clean_Processing!A:A, 0)) -> Butler Ltd | I14: =INDEX(Products!C:C, MATCH(B14,Clean_Processing!A:A, 0)) -> Electronics | J14: =INDEX(Shipments!C:C, MATCH(B14,Clean_Processing!A:A, 0)) -> 22 | K14: =INDEX(Shipments!D:D, MATCH(C14,Clean_Processing!A:A, 0)) -> Bike | L14: 44974 | M14: Delivered | N14: =IFERROR(INDEX(Shipments!G:G, MATCH(J14, Clean_Processing!C:C, 0)), "") -> 461.69547 | O14: 17268.065 | P14: 0.97395929 | Q14: =INDEX(Products!D:D, MATCH(C14, Clean_Processing!A:A, 0)) -> 206.16 | R14: 17729.76 | S14: 17061.905 | T14: 0.96233139 | W14: New Jerome
A15: 14 | B15: 22 | C15: 8 | D15: 64 | E15: 45121 | F15: 2023 | G15: =INDEX(Products!B:B, MATCH(C15,Clean_Processing!A:A, 0)) -> Science | H15: =INDEX(Suppliers!B:B, MATCH(B15, Clean_Processing!A:A, 0)) -> Martinez PLC | I15: =INDEX(Products!C:C, MATCH(B15,Clean_Processing!A:A, 0)) -> Medical | J15: =INDEX(Shipments!C:C, MATCH(B15,Clean_Processing!A:A, 0)) -> 74 | K15: =INDEX(Shipments!D:D, MATCH(C15,Clean_Processing!A:A, 0)) -> Drone | L15: 45115 | M15: Delivered | N15: =IFERROR(INDEX(Shipments!G:G, MATCH(J15, Clean_Processing!C:C, 0)), "") -> 131.6184 | O15: 21381.342 | P15: 0.9938819 | Q15: =INDEX(Products!D:D, MATCH(C15, Clean_Processing!A:A, 0)) -> 336.14 | R15: 21512.96 | S15: 21045.202 | T15: 0.9782569 | W15: Gonzalesstad
A16: 15 | B16: 12 | C16: 125 | D16: 28 | E16: 45093 | F16: 2023 | G16: =INDEX(Products!B:B, MATCH(C16,Clean_Processing!A:A, 0)) -> Hold | H16: =INDEX(Suppliers!B:B, MATCH(B16, Clean_Processing!A:A, 0)) -> Yoder-Thompson | I16: =INDEX(Products!C:C, MATCH(B16,Clean_Processing!A:A, 0)) -> Electronics | J16: =INDEX(Shipments!C:C, MATCH(B16,Clean_Processing!A:A, 0)) -> 47 | K16: =INDEX(Shipments!D:D, MATCH(C16,Clean_Processing!A:A, 0)) -> Van | L16: 45229 | M16: Delivered | N16: =IFERROR(INDEX(Shipments!G:G, MATCH(J16, Clean_Processing!C:C, 0)), "") -> 119.57635 | O16: 6791.3836 | P16: 0.98269758 | Q16: =INDEX(Products!D:D, MATCH(C16, Clean_Processing!A:A, 0)) -> 246.82 | R16: 6910.96 | S16: 6544.5636 | T16: 0.94698329 | U16: 136 | V16: Slow | W16: Hugheston
A17: 16 | B17: 17 | C17: 88 | D17: 36 | E17: 45108 | F17: 2023 | G17: =INDEX(Products!B:B, MATCH(C17,Clean_Processing!A:A, 0)) -> City | H17: =INDEX(Suppliers!B:B, MATCH(B17, Clean_Processing!A:A, 0)) -> Acevedo PLC | I17: =INDEX(Products!C:C, MATCH(B17,Clean_Processing!A:A, 0)) -> Medical | J17: =INDEX(Shipments!C:C, MATCH(B17,Clean_Processing!A:A, 0)) -> 12 | K17: =INDEX(Shipments!D:D, MATCH(C17,Clean_Processing!A:A, 0)) -> Bike | L17: 45123 | M17: Delivered | N17: =IFERROR(INDEX(Shipments!G:G, MATCH(J17, Clean_Processing!C:C, 0)), "") -> 435.71256 | O17: 6797.0474 | P17: 0.93975847 | Q17: =INDEX(Products!D:D, MATCH(C17, Clean_Processing!A:A, 0)) -> 200.91 | R17: 7232.76 | S17: 6596.1374 | T17: 0.91198069 | U17: 15 | V17: Slow | W17: North Austinton
A18: 17 | B18: 45 | C18: 71 | D18: 72 | E18: 45232 | F18: 2023 | G18: =INDEX(Products!B:B, MATCH(C18,Clean_Processing!A:A, 0)) -> Much | H18: =INDEX(Suppliers!B:B, MATCH(B18, Clean_Processing!A:A, 0)) -> Horton-Huffman | I18: =INDEX(Products!C:C, MATCH(B18,Clean_Processing!A:A, 0)) -> Furniture | J18: =INDEX(Shipments!C:C, MATCH(B18,Clean_Processing!A:A, 0)) -> 60 | K18: =INDEX(Shipments!D:D, MATCH(C18,Clean_Processing!A:A, 0)) -> Bike | L18: 45289 | M18: Delivered | N18: =IFERROR(INDEX(Shipments!G:G, MATCH(J18, Clean_Processing!C:C, 0)), "") -> 257.20978 | O18: 2958.3102 | P18: 0.9200099 | Q18: =INDEX(Products!D:D, MATCH(C18, Clean_Processing!A:A, 0)) -> 44.66 | R18: 3215.52 | S18: 2913.6502 | T18: 0.90612101 | U18: 57 | V18: Slow | W18: Lake Christopher
A19: 18 | B19: 34 | C19: 49 | D19: 11 | E19: 44932 | F19: 2023 | G19: =INDEX(Products!B:B, MATCH(C19,Clean_Processing!A:A, 0)) -> Ability | H19: =INDEX(Suppliers!B:B, MATCH(B19, Clean_Processing!A:A, 0)) -> Singh Ltd | I19: =INDEX(Products!C:C, MATCH(B19,Clean_Processing!A:A, 0)) -> Clothing | J19: =INDEX(Shipments!C:C, MATCH(B19,Clean_Processing!A:A, 0)) -> 68 | K19: =INDEX(Shipments!D:D, MATCH(C19,Clean_Processing!A:A, 0)) -> Drone | L19: 45054 | M19: Delivered | N19: =IFERROR(INDEX(Shipments!G:G, MATCH(J19, Clean_Processing!C:C, 0)), "") -> 74.899801 | O19: 2043.5902 | P19: 0.96464472 | Q19: =INDEX(Products!D:D, MATCH(C19, Clean_Processing!A:A, 0)) -> 192.59 | R19: 2118.49 | S19: 1851.0002 | T19: 0.87373563 | U19: 122 | V19: Slow | W19: Port Stevenberg
A20: 19 | B20: 47 | C20: 105 | D20: 63 | E20: 45050 | F20: 2023 | G20: =INDEX(Products!B:B, MATCH(C20,Clean_Processing!A:A, 0)) -> Herself | H20: =INDEX(Suppliers!B:B, MATCH(B20, Clean_Processing!A:A, 0)) -> Gutierrez and Sons | I20: =INDEX(Products!C:C, MATCH(B20,Clean_Processing!A:A, 0)) -> Electronics | J20: =INDEX(Shipments!C:C, MATCH(B20,Clean_Processing!A:A, 0)) -> 45 | K20: =INDEX(Shipments!D:D, MATCH(C20,Clean_Processing!A:A, 0)) -> 0 | L20: 45004 | M20: Delivered | N20: =IFERROR(INDEX(Shipments!G:G, MATCH(J20, Clean_Processing!C:C, 0)), "") -> 207.67191 | O20: 26107.428 | P20: 0.99210826 | Q20: =INDEX(Products!D:D, MATCH(C20, Clean_Processing!A:A, 0)) -> 417.7 | R20: 26315.1 | S20: 25689.728 | T20: 0.97623524 | W20: West Lisa
A21: 20 | B21: 49 | C21: 62 | D21: 89 | E21: 45211 | F21: 2023 | G21: =INDEX(Products!B:B, MATCH(C21,Clean_Processing!A:A, 0)) -> Even | H21: =INDEX(Suppliers!B:B, MATCH(B21, Clean_Processing!A:A, 0)) -> Hawkins Inc | I21: =INDEX(Products!C:C, MATCH(B21,Clean_Processing!A:A, 0)) -> Electronics | J21: =INDEX(Shipments!C:C, MATCH(B21,Clean_Processing!A:A, 0)) -> 71 | K21: =INDEX(Shipments!D:D, MATCH(C21,Clean_Processing!A:A, 0)) -> Van | L21: 45022 | M21: Delivered | N21: =IFERROR(INDEX(Shipments!G:G, MATCH(J21, Clean_Processing!C:C, 0)), "") -> 55.264623 | O21: 25905.145 | P21: 0.9978712 | Q21: =INDEX(Products!D:D, MATCH(C21, Clean_Processing!A:A, 0)) -> 291.69 | R21: 25960.41 | S21: 25613.455 | T21: 0.98663524 | W21: Welchborough
A22: 21 | B22: 42 | C22: 183 | D22: 63 | E22: 45170 | F22: 2023 | G22: =INDEX(Products!B:B, MATCH(C22,Clean_Processing!A:A, 0)) -> Trip | H22: =INDEX(Suppliers!B:B, MATCH(B22, Clean_Processing!A:A, 0)) -> Sullivan-Smith | I22: =INDEX(Products!C:C, MATCH(B22,Clean_Processing!A:A, 0)) -> Medical | J22: =INDEX(Shipments!C:C, MATCH(B22,Clean_Processing!A:A, 0)) -> 98 | K22: =INDEX(Shipments!D:D, MATCH(C22,Clean_Processing!A:A, 0)) -> 0 | L22: 44961 | M22: Delivered | N22: =IFERROR(INDEX(Shipments!G:G, MATCH(J22, Clean_Processing!C:C, 0)), "") -> 419.97811 | O22: 632.75189 | P22: 0.60105809 | Q22: =INDEX(Products!D:D, MATCH(C22, Clean_Processing!A:A, 0)) -> 16.71 | R22: 1052.73 | S22: 616.04189 | T22: 0.58518508 | W22: Lake Bethany
A23: 22 | B23: 2 | C23: 24 | D23: 38 | E23: 45156 | F23: 2023 | G23: =INDEX(Products!B:B, MATCH(C23,Clean_Processing!A:A, 0)) -> Message | H23: =INDEX(Suppliers!B:B, MATCH(B23, Clean_Processing!A:A, 0)) -> Holmes, Duncan and Reed | I23: =INDEX(Products!C:C, MATCH(B23,Clean_Processing!A:A, 0)) -> Electronics | J23: =INDEX(Shipments!C:C, MATCH(B23,Clean_Processing!A:A, 0)) -> 92 | K23: =INDEX(Shipments!D:D, MATCH(C23,Clean_Processing!A:A, 0)) -> Van | L23: 45262 | M23: Delivered | N23: =IFERROR(INDEX(Shipments!G:G, MATCH(J23, Clean_Processing!C:C, 0)), "") -> 455.91997 | O23: 1585.44 | P23: 0.77665871 | Q23: =INDEX(Products!D:D, MATCH(C23, Clean_Processing!A:A, 0)) -> 53.72 | R23: 2041.36 | S23: 1531.72 | T23: 0.75034292 | U23: 106 | V23: Slow | W23: Port Micheleland
A24: 23 | B24: 26 | C24: 178 | D24: 32 | E24: 45040 | F24: 2023 | G24: =INDEX(Products!B:B, MATCH(C24,Clean_Processing!A:A, 0)) -> Magazine | H24: =INDEX(Suppliers!B:B, MATCH(B24, Clean_Processing!A:A, 0)) -> Miller-Pennington | I24: =INDEX(Products!C:C, MATCH(B24,Clean_Processing!A:A, 0)) -> Medical | J24: =INDEX(Shipments!C:C, MATCH(B24,Clean_Processing!A:A, 0)) -> 71 | K24: =INDEX(Shipments!D:D, MATCH(C24,Clean_Processing!A:A, 0)) -> Bike | L24: 45012 | M24: Delivered | N24: =IFERROR(INDEX(Shipments!G:G, MATCH(J24, Clean_Processing!C:C, 0)), "") -> 55.264623 | O24: 13039.455 | P24: 0.99577963 | Q24: =INDEX(Products!D:D, MATCH(C24, Clean_Processing!A:A, 0)) -> 409.21 | R24: 13094.72 | S24: 12630.245 | T24: 0.96452963 | W24: New Ericfort
A25: 24 | B25: 43 | C25: 149 | D25: 48 | E25: 45083 | F25: 2023 | G25: =INDEX(Products!B:B, MATCH(C25,Clean_Processing!A:A, 0)) -> Subject | H25: =INDEX(Suppliers!B:B, MATCH(B25, Clean_Processing!A:A, 0)) -> Johnson, Knight and Dawson | I25: =INDEX(Products!C:C, MATCH(B25,Clean_Processing!A:A, 0)) -> Food | J25: =INDEX(Shipments!C:C, MATCH(B25,Clean_Processing!A:A, 0)) -> 3 | K25: =INDEX(Shipments!D:D, MATCH(C25,Clean_Processing!A:A, 0)) -> 0 | L25: 45290 | M25: Delivered | N25: =IFERROR(INDEX(Shipments!G:G, MATCH(J25, Clean_Processing!C:C, 0)), "") -> 254.79639 | O25: 18901.044 | P25: 0.98669876 | Q25: =INDEX(Products!D:D, MATCH(C25, Clean_Processing!A:A, 0)) -> 399.08 | R25: 19155.84 | S25: 18501.964 | T25: 0.96586543 | U25: 207 | V25: Slow | W25: Spencermouth
A26: 25 | B26: 36 | C26: 136 | D26: 45 | E26: 45169 | F26: 2023 | G26: =INDEX(Products!B:B, MATCH(C26,Clean_Processing!A:A, 0)) -> Product | H26: =INDEX(Suppliers!B:B, MATCH(B26, Clean_Processing!A:A, 0)) -> Petersen Inc | I26: =INDEX(Products!C:C, MATCH(B26,Clean_Processing!A:A, 0)) -> Electronics | J26: =INDEX(Shipments!C:C, MATCH(B26,Clean_Processing!A:A, 0)) -> 74 | K26: =INDEX(Shipments!D:D, MATCH(C26,Clean_Processing!A:A, 0)) -> 0 | L26: 45021 | M26: Delivered | N26: =IFERROR(INDEX(Shipments!G:G, MATCH(J26, Clean_Processing!C:C, 0)), "") -> 131.6184 | O26: 12381.982 | P26: 0.98948197 | Q26: =INDEX(Products!D:D, MATCH(C26, Clean_Processing!A:A, 0)) -> 278.08 | R26: 12513.6 | S26: 12103.902 | T26: 0.96725975 | W26: Port Kimberly
A27: 26 | B27: 48 | C27: 141 | D27: 43 | E27: 45144 | F27: 2023 | G27: =INDEX(Products!B:B, MATCH(C27,Clean_Processing!A:A, 0)) -> Interesting | H27: =INDEX(Suppliers!B:B, MATCH(B27, Clean_Processing!A:A, 0)) -> Thompson, Shaw and Brown | I27: =INDEX(Products!C:C, MATCH(B27,Clean_Processing!A:A, 0)) -> Furniture | J27: =INDEX(Shipments!C:C, MATCH(B27,Clean_Processing!A:A, 0)) -> 10 | K27: =INDEX(Shipments!D:D, MATCH(C27,Clean_Processing!A:A, 0)) -> Bike | L27: 45115 | M27: Delivered | N27: =IFERROR(INDEX(Shipments!G:G, MATCH(J27, Clean_Processing!C:C, 0)), "") -> 445.89732 | O27: 19009.023 | P27: 0.97708049 | Q27: =INDEX(Products!D:D, MATCH(C27, Clean_Processing!A:A, 0)) -> 452.44 | R27: 19454.92 | S27: 18556.583 | T27: 0.95382467 | W27: Grahamfort
A28: 27 | B28: 45 | C28: 117 | D28: 35 | E28: 45107 | F28: 2023 | G28: =INDEX(Products!B:B, MATCH(C28,Clean_Processing!A:A, 0)) -> Girl | H28: =INDEX(Suppliers!B:B, MATCH(B28, Clean_Processing!A:A, 0)) -> Horton-Huffman | I28: =INDEX(Products!C:C, MATCH(B28,Clean_Processing!A:A, 0)) -> Furniture | J28: =INDEX(Shipments!C:C, MATCH(B28,Clean_Processing!A:A, 0)) -> 60 | K28: =INDEX(Shipments!D:D, MATCH(C28,Clean_Processing!A:A, 0)) -> Truck | L28: 44932 | M28: Delivered | N28: =IFERROR(INDEX(Shipments!G:G, MATCH(J28, Clean_Processing!C:C, 0)), "") -> 257.20978 | O28: 1772.0902 | P28: 0.87325197 | Q28: =INDEX(Products!D:D, MATCH(C28, Clean_Processing!A:A, 0)) -> 57.98 | R28: 2029.3 | S28: 1714.1102 | T28: 0.84468054 | W28: North April
A29: 28 | B29: 17 | C29: 60 | D29: 16 | E29: 45083 | F29: 2023 | G29: =INDEX(Products!B:B, MATCH(C29,Clean_Processing!A:A, 0)) -> Including | H29: =INDEX(Suppliers!B:B, MATCH(B29, Clean_Processing!A:A, 0)) -> Acevedo PLC | I29: =INDEX(Products!C:C, MATCH(B29,Clean_Processing!A:A, 0)) -> Medical | J29: =INDEX(Shipments!C:C, MATCH(B29,Clean_Processing!A:A, 0)) -> 12 | K29: =INDEX(Shipments!D:D, MATCH(C29,Clean_Processing!A:A, 0)) -> Bike | L29: 44940 | M29: Delivered | N29: =IFERROR(INDEX(Shipments!G:G, MATCH(J29, Clean_Processing!C:C, 0)), "") -> 435.71256 | O29: 1994.2074 | P29: 0.82068852 | Q29: =INDEX(Products!D:D, MATCH(C29, Clean_Processing!A:A, 0)) -> 151.87 | R29: 2429.92 | S29: 1842.3374 | T29: 0.75818852 | W29: Garciahaven
A30: 29 | B30: 21 | C30: 31 | D30: 96 | E30: 45025 | F30: 2023 | G30: =INDEX(Products!B:B, MATCH(C30,Clean_Processing!A:A, 0)) -> Last | H30: =INDEX(Suppliers!B:B, MATCH(B30, Clean_Processing!A:A, 0)) -> Delgado Ltd | I30: =INDEX(Products!C:C, MATCH(B30,Clean_Processing!A:A, 0)) -> Clothing | J30: =INDEX(Shipments!C:C, MATCH(B30,Clean_Processing!A:A, 0)) -> 67 | K30: =INDEX(Shipments!D:D, MATCH(C30,Clean_Processing!A:A, 0)) -> Bike | L30: 44996 | M30: Delivered | N30: =IFERROR(INDEX(Shipments!G:G, MATCH(J30, Clean_Processing!C:C, 0)), "") -> 289.43524 | O30: 20238.245 | P30: 0.98590025 | Q30: =INDEX(Products!D:D, MATCH(C30, Clean_Processing!A:A, 0)) -> 213.83 | R30: 20527.68 | S30: 20024.415 | T30: 0.97548358 | W30: South Ravenstad
A31: 30 | B31: 49 | C31: 177 | D31: 24 | E31: 45201 | F31: 2023 | G31: =INDEX(Products!B:B, MATCH(C31,Clean_Processing!A:A, 0)) -> Any | H31: =INDEX(Suppliers!B:B, MATCH(B31, Clean_Processing!A:A, 0)) -> Hawkins Inc | I31: =INDEX(Products!C:C, MATCH(B31,Clean_Processing!A:A, 0)) -> Electronics | J31: =INDEX(Shipments!C:C, MATCH(B31,Clean_Processing!A:A, 0)) -> 71 | K31: =INDEX(Shipments!D:D, MATCH(C31,Clean_Processing!A:A, 0)) -> Van | L31: 45053 | M31: Delivered | N31: =IFERROR(INDEX(Shipments!G:G, MATCH(J31, Clean_Processing!C:C, 0)), "") -> 55.264623 | O31: 2707.1354 | P31: 0.97999398 | Q31: =INDEX(Products!D:D, MATCH(C31, Clean_Processing!A:A, 0)) -> 115.1 | R31: 2762.4 | S31: 2592.0354 | T31: 0.93832732 | W31: Riosview
A32: 31 | B32: 14 | C32: 190 | D32: 62 | E32: 45025 | F32: 2023 | G32: =INDEX(Products!B:B, MATCH(C32,Clean_Processing!A:A, 0)) -> Listen | H32: =INDEX(Suppliers!B:B, MATCH(B32, Clean_Processing!A:A, 0)) -> Walsh-Perez | I32: =INDEX(Products!C:C, MATCH(B32,Clean_Processing!A:A, 0)) -> Electronics | J32: =INDEX(Shipments!C:C, MATCH(B32,Clean_Processing!A:A, 0)) -> 35 | K32: =INDEX(Shipments!D:D, MATCH(C32,Clean_Processing!A:A, 0)) -> Van | L32: 45163 | M32: Delivered | N32: =IFERROR(INDEX(Shipments!G:G, MATCH(J32, Clean_Processing!C:C, 0)), "") -> 330.20981 | O32: 12245.87 | P32: 0.97374303 | Q32: =INDEX(Products!D:D, MATCH(C32, Clean_Processing!A:A, 0)) -> 202.84 | R32: 12576.08 | S32: 12043.03 | T32: 0.95761399 | U32: 138 | V32: Slow | W32: Robertstad
A33: 32 | B33: 47 | C33: 151 | D33: 98 | E33: 45068 | F33: 2023 | G33: =INDEX(Products!B:B, MATCH(C33,Clean_Processing!A:A, 0)) -> Mother | H33: =INDEX(Suppliers!B:B, MATCH(B33, Clean_Processing!A:A, 0)) -> Gutierrez and Sons | I33: =INDEX(Products!C:C, MATCH(B33,Clean_Processing!A:A, 0)) -> Electronics | J33: =INDEX(Shipments!C:C, MATCH(B33,Clean_Processing!A:A, 0)) -> 45 | K33: =INDEX(Shipments!D:D, MATCH(C33,Clean_Processing!A:A, 0)) -> Bike | L33: 45054 | M33: Delivered | N33: =IFERROR(INDEX(Shipments!G:G, MATCH(J33, Clean_Processing!C:C, 0)), "") -> 207.67191 | O33: 43889.388 | P33: 0.99529057 | Q33: =INDEX(Products!D:D, MATCH(C33, Clean_Processing!A:A, 0)) -> 449.97 | R33: 44097.06 | S33: 43439.418 | T33: 0.98508649 | W33: Samueltown
A34: 33 | B34: 39 | C34: 73 | D34: 13 | E34: 45195 | F34: 2023 | G34: =INDEX(Products!B:B, MATCH(C34,Clean_Processing!A:A, 0)) -> Attorney | H34: =INDEX(Suppliers!B:B, MATCH(B34, Clean_Processing!A:A, 0)) -> Garcia-Logan | I34: =INDEX(Products!C:C, MATCH(B34,Clean_Processing!A:A, 0)) -> Electronics | J34: =INDEX(Shipments!C:C, MATCH(B34,Clean_Processing!A:A, 0)) -> 15 | K34: =INDEX(Shipments!D:D, MATCH(C34,Clean_Processing!A:A, 0)) -> Drone | L34: 45120 | M34: Delivered | N34: =IFERROR(INDEX(Shipments!G:G, MATCH(J34, Clean_Processing!C:C, 0)), "") -> 99.677513 | O34: 3794.3425 | P34: 0.97440241 | Q34: =INDEX(Products!D:D, MATCH(C34, Clean_Processing!A:A, 0)) -> 299.54 | R34: 3894.02 | S34: 3494.8025 | T34: 0.89747934 | W34: New Madison
A35: 34 | B35: 19 | C35: 59 | D35: 47 | E35: 45026 | F35: 2023 | G35: =INDEX(Products!B:B, MATCH(C35,Clean_Processing!A:A, 0)) -> Play | H35: =INDEX(Suppliers!B:B, MATCH(B35, Clean_Processing!A:A, 0)) -> King LLC | I35: =INDEX(Products!C:C, MATCH(B35,Clean_Processing!A:A, 0)) -> Electronics | J35: =INDEX(Shipments!C:C, MATCH(B35,Clean_Processing!A:A, 0)) -> 58 | K35: =INDEX(Shipments!D:D, MATCH(C35,Clean_Processing!A:A, 0)) -> Van | L35: 45179 | M35: Delivered | N35: =IFERROR(INDEX(Shipments!G:G, MATCH(J35, Clean_Processing!C:C, 0)), "") -> 444.6528 | O35: 3391.4872 | P35: 0.88408849 | Q35: =INDEX(Products!D:D, MATCH(C35, Clean_Processing!A:A, 0)) -> 81.62 | R35: 3836.14 | S35: 3309.8672 | T35: 0.86281189 | U35: 153 | V35: Slow | W35: South Tylerstad
A36: 35 | B36: 20 | C36: 4 | D36: 91 | E36: 45018 | F36: 2023 | G36: =INDEX(Products!B:B, MATCH(C36,Clean_Processing!A:A, 0)) -> Step | H36: =INDEX(Suppliers!B:B, MATCH(B36, Clean_Processing!A:A, 0)) -> Cooper-Jones | I36: =INDEX(Products!C:C, MATCH(B36,Clean_Processing!A:A, 0)) -> Medical | J36: =INDEX(Shipments!C:C, MATCH(B36,Clean_Processing!A:A, 0)) -> 36 | K36: =INDEX(Shipments!D:D, MATCH(C36,Clean_Processing!A:A, 0)) -> Drone | L36: 45168 | M36: Delivered | N36: =IFERROR(INDEX(Shipments!G:G, MATCH(J36, Clean_Processing!C:C, 0)), "") -> 177.62958 | O36: 41061.75 | P36: 0.99569272 | Q36: =INDEX(Products!D:D, MATCH(C36, Clean_Processing!A:A, 0)) -> 453.18 | R36: 41239.38 | S36: 40608.57 | T36: 0.98470371 | U36: 150 | V36: Slow | W36: New Briannabury
A37: 36 | B37: 9 | C37: 71 | D37: 6 | E37: 45200 | F37: 2023 | G37: =INDEX(Products!B:B, MATCH(C37,Clean_Processing!A:A, 0)) -> Much | H37: =INDEX(Suppliers!B:B, MATCH(B37, Clean_Processing!A:A, 0)) -> Aguirre and Sons | I37: =INDEX(Products!C:C, MATCH(B37,Clean_Processing!A:A, 0)) -> Electronics | J37: =INDEX(Shipments!C:C, MATCH(B37,Clean_Processing!A:A, 0)) -> 32 | K37: =INDEX(Shipments!D:D, MATCH(C37,Clean_Processing!A:A, 0)) -> Bike | L37: 45135 | M37: Delivered | N37: =IFERROR(INDEX(Shipments!G:G, MATCH(J37, Clean_Processing!C:C, 0)), "") -> 173.69079 | O37: 94.269213 | P37: 0.3518033 | Q37: =INDEX(Products!D:D, MATCH(C37, Clean_Processing!A:A, 0)) -> 44.66 | R37: 267.96 | S37: 49.609213 | T37: 0.18513664 | W37: Evansberg
A38: 37 | B38: 36 | C38: 75 | D38: 90 | E38: 44954 | F38: 2023 | G38: =INDEX(Products!B:B, MATCH(C38,Clean_Processing!A:A, 0)) -> People | H38: =INDEX(Suppliers!B:B, MATCH(B38, Clean_Processing!A:A, 0)) -> Petersen Inc | I38: =INDEX(Products!C:C, MATCH(B38,Clean_Processing!A:A, 0)) -> Electronics | J38: =INDEX(Shipments!C:C, MATCH(B38,Clean_Processing!A:A, 0)) -> 74 | K38: =INDEX(Shipments!D:D, MATCH(C38,Clean_Processing!A:A, 0)) -> Drone | L38: 45186 | M38: Delivered | N38: =IFERROR(INDEX(Shipments!G:G, MATCH(J38, Clean_Processing!C:C, 0)), "") -> 131.6184 | O38: 10797.082 | P38: 0.98795663 | Q38: =INDEX(Products!D:D, MATCH(C38, Clean_Processing!A:A, 0)) -> 121.43 | R38: 10928.7 | S38: 10675.652 | T38: 0.97684552 | U38: 232 | V38: Slow | W38: Port Arthurfort
A39: 38 | B39: 41 | C39: 193 | D39: 63 | E39: 44991 | F39: 2023 | G39: =INDEX(Products!B:B, MATCH(C39,Clean_Processing!A:A, 0)) -> Hold | H39: =INDEX(Suppliers!B:B, MATCH(B39, Clean_Processing!A:A, 0)) -> Gomez and Sons | I39: =INDEX(Products!C:C, MATCH(B39,Clean_Processing!A:A, 0)) -> Food | J39: =INDEX(Shipments!C:C, MATCH(B39,Clean_Processing!A:A, 0)) -> 28 | K39: =INDEX(Shipments!D:D, MATCH(C39,Clean_Processing!A:A, 0)) -> 0 | L39: 44967 | M39: Delivered | N39: =IFERROR(INDEX(Shipments!G:G, MATCH(J39, Clean_Processing!C:C, 0)), "") -> 362.48678 | O39: 29242.473 | P39: 0.98775588 | Q39: =INDEX(Products!D:D, MATCH(C39, Clean_Processing!A:A, 0)) -> 469.92 | R39: 29604.96 | S39: 28772.553 | T39: 0.97188286 | W39: Marcusfort
A40: 39 | B40: 1 | C40: 147 | D40: 37 | E40: 44979 | F40: 2023 | G40: =INDEX(Products!B:B, MATCH(C40,Clean_Processing!A:A, 0)) -> Congress | H40: =INDEX(Suppliers!B:B, MATCH(B40, Clean_Processing!A:A, 0)) -> Robinson, Beasley and Hall | I40: =INDEX(Products!C:C, MATCH(B40,Clean_Processing!A:A, 0)) -> Electronics | J40: =INDEX(Shipments!C:C, MATCH(B40,Clean_Processing!A:A, 0)) -> 28 | K40: =INDEX(Shipments!D:D, MATCH(C40,Clean_Processing!A:A, 0)) -> Drone | L40: 45238 | M40: Delivered | N40: =IFERROR(INDEX(Shipments!G:G, MATCH(J40, Clean_Processing!C:C, 0)), "") -> 362.48678 | O40: 5468.3432 | P40: 0.93783273 | Q40: =INDEX(Products!D:D, MATCH(C40, Clean_Processing!A:A, 0)) -> 157.59 | R40: 5830.83 | S40: 5310.7532 | T40: 0.9108057 | U40: 259 | V40: Slow | W40: North Stephanieside
...

Sheet Products
A1: product_id | B1: product_name | C1: category | D1: unit_price
A2: 1 | B2: Local | C2: Electronics | D2: 40.14
A3: 2 | B3: Receive | C3: Electronics | D3: 317.4
A4: 3 | B4: Near | C4: Food | D4: 118.33
A5: 4 | B5: Step | C5: Clothing | D5: 453.18
A6: 5 | B6: Stage | C6: Clothing | D6: 430.52
A7: 6 | B7: Year | C7: Clothing | D7: 40.07
A8: 7 | B8: Last | C8: Electronics | D8: 122.81
A9: 8 | B9: Science | C9: Medical | D9: 336.14
A10: 9 | B10: Fill | C10: Electronics | D10: 111.05
A11: 10 | B11: Sport | C11: Medical | D11: 70.49
A12: 11 | B12: Know | C12: Furniture | D12: 468.08
A13: 12 | B13: Small | C13: Electronics | D13: 287.67
... A201: 200 | B201: Pressure | C201: Electronics | D201: 220.11

Sheet Shipments
A1: shipment_id | B1: order_id | C1: vehicle_id | D1: Vehicle_type | E1: scheduled_delivery | F1: actual_delivery | G1: delivery_cost
A2: 1 | B2: 3655 | C2: 28 | D2: =INDEX(Vehicles!B:B, MATCH(C2, Shipments!C:C, 0)) -> Bike | E2: 45045 | F2: 45044 | G2: 425.16828
A3: 2 | B3: 3347 | C3: 92 | D3: =INDEX(Vehicles!B:B, MATCH(C3, Shipments!C:C, 0)) -> Drone | E3: 45154 | F3: 45156 | G3: 83.688912
A4: 3 | B4: 3150 | C4: 79 | D4: =INDEX(Vehicles!B:B, MATCH(C4, Shipments!C:C, 0)) -> Truck | E4: 45121 | F4: 45120 | G4: 275.21966
A5: 4 | B5: 2226 | C5: 27 | D5: =INDEX(Vehicles!B:B, MATCH(C5, Shipments!C:C, 0)) -> Drone | E5: 45271 | F5: 45273 | G5: 223.95864
A6: 5 | B6: 4293 | C6: 44 | D6: =INDEX(Vehicles!B:B, MATCH(C6, Shipments!C:C, 0)) -> Van | E6: 45091 | F6: 45090 | G6: 254.52575
A7: 6 | B7: 3178 | C7: 57 | D7: =INDEX(Vehicles!B:B, MATCH(C7, Shipments!C:C, 0)) -> Bike | E7: 45237 | F7: 45237 | G7: 192.75092
A8: 7 | B8: 634 | C8: 77 | D8: =INDEX(Vehicles!B:B, MATCH(C8, Shipments!C:C, 0)) -> Truck | E8: 45284 | F8: 45286 | G8: 92.50701
A9: 8 | B9: 3310 | C9: 27 | D9: =INDEX(Vehicles!B:B, MATCH(C9, Shipments!C:C, 0)) -> Drone | E9: 45038 | F9: 45039 | G9: 183.10009
A10: 9 | B10: 2246 | C10: 32 | D10: =INDEX(Vehicles!B:B, MATCH(C10, Shipments!C:C, 0)) -> Truck | E10: 45075 | F10: 45075 | G10: 195.92759
A11: 10 | B11: 3848 | C11: 4 | D11: =INDEX(Vehicles!B:B, MATCH(C11, Shipments!C:C, 0)) -> Van | E11: 45278 | F11: 45281 | G11: 129.59572
A12: 11 | B12: 530 | C12: 58 | D12: =INDEX(Vehicles!B:B, MATCH(C12, Shipments!C:C, 0)) -> Bike | E12: 45292 | F12: 45291 | G12: 200.54624
A13: 12 | B13: 2828 | C13: 47 | D13: =INDEX(Vehicles!B:B, MATCH(C13, Shipments!C:C, 0)) -> Drone | E13: 45122 | F13: 45121 | G13: 250.56916
... A4001: 4000 | B4001: 1025 | C4001: 96 | D4001: =INDEX(Vehicles!B:B, MATCH(C4001, Shipments!C:C, 0)) -> 0 | E4001: 45126 | F4001: 45127 | G4001: 179.2035

Sheet Suppliers
A1: supplier_id | B1: supplier_name | C1: country
A2: 1 | B2: Robinson, Beasley and Hall | C2: Cambodia
A3: 2 | B3: Holmes, Duncan and Reed | C3: Croatia
A4: 3 | B4: Mendez-Miller | C4: Samoa
A5: 4 | B5: Martin, Dean and Glenn | C5: Cape Verde
A6: 5 | B6: Logan-Fernandez | C6: Madagascar
A7: 6 | B7: Dunn Ltd | C7: Iceland
A8: 7 | B8: Holloway-Mcconnell | C8: Jersey
A9: 8 | B9: Andrews-Jordan | C9: South Africa
A10: 9 | B10: Aguirre and Sons | C10: Saint Kitts and Nevis
A11: 10 | B11: Wilson, Jones and Gregory | C11: Venezuela
A12: 11 | B12: Cross Inc | C12: Azerbaijan
A13: 12 | B13: Yoder-Thompson | C13: Puerto Rico
... A51: 50 | B51: Waters-Robinson | C51: United Arab Emirates

Sheet Vehicles
A1: vehicle_id | B1: vehicle_type | C1: capacity_kg | D1: driver_name
A2: 1 | B2: Bike | C2: 1351 | D2: Lori Wilson
A3: 2 | B3: Drone | C3: 1852 | D3: Sherry Carney
A4: 3 | B4: Truck | C4: 626 | D4: Holly Gould
A5: 4 | B5: Drone | C5: 3498 | D5: Matthew Jackson
A6: 5 | B6: Van | C6: 3439 | D6: Mark Taylor
A7: 6 | B7: Bike | C7: 2810 | D7: Caitlyn Graves
A8: 7 | B8: Truck | C8: 4545 | D8: Jose Carney
A9: 8 | B9: Drone | C9: 3916 | D9: Troy Cooper
A10: 9 | B10: Truck | C10: 3506 | D10: James Hendricks
A11: 10 | B11: Van | C11: 610 | D11: Joseph Parks
A12: 11 | B12: Bike | C12: 1794 | D12: Pamela Leonard
A13: 12 | B13: Drone | C13: 3541 | D13: Eugene Brown
... A101: 100 | B101: Drone | C101: 934 | D101: Kyle Sharp
